<?xml version="1.0"?>
<robot xmlns:xacro="http://www.ros.org/wiki/xacro">

	<xacro:macro name="drive_wheel" params="prefix right:=0">
	
		<xacro:property name="left" value="${1 - right}"/>
		<xacro:property name="front" value="${1 - back}"/>
		<xacro:property name="origin">
			<origin xyz="0 0 -0.005" rpy="0 0 ${PI / 2 - right * PI}" />
		</xacro:property>

		<link name="${prefix}_drive_wheel_link">
			<inertial>
				<xacro:insert_block name="origin"/>
				<mass value="3"/>
				<xacro:insert_block name="default_inertia"/>
			</inertial>

			<visual>
				<xacro:insert_block name="origin"/>
				<geometry>
					<mesh filename="package://intellwheels_desc/meshes/wheel.dae"/>
				</geometry>
			</visual>

			<collision>
				<origin rpy="${PI / 2} 0 0"/>
				<geometry>
					<cylinder radius="0.184" length="0.07"/>
				</geometry>
			</collision>
		</link>

		<joint name="${prefix}_drive_wheel_joint" type="continuous">
			<origin xyz="0 ${left * 0.294 - right * 0.278} 0"/>
			<parent link="base_link"/>
			<child link="${prefix}_drive_wheel_link"/>
			<axis xyz="0 1 0"/>
		</joint>
	</xacro:macro>

</robot>
