<?xml version="1.0"?>
<!-- created with Phobos 0.7 -->
<sdf version="1.6">
  <model name="wheelchair_base_model">


    <link name="base_footprint"/>

    <link name="base_link">
      <pose>0 0 0.28 0 0 0</pose>
      <inertial>
        <mass>145</mass>
        <inertia>
          <ixx>3.64053</ixx>
          <ixy>-0.06186</ixy>
          <ixz>-0.00036</ixz>
          <iyy>2.77052</iyy>
          <iyz>0.35856</iyz>
          <izz>0.20333</izz>
        </inertia>
      </inertial>

      <collision name="Wheelchair1">
        <pose>0.575 0.0 -0.14 0.08 0 -1.57</pose>
        <geometry>
          <box>
            <size>0.25 0.2 0.021</size>
          </box>
        </geometry>
      </collision>
      <collision name="Wheelchair2">
        <pose>-0.4 0.0 0.8 0.25 0 -1.57</pose>
        <geometry>
          <box>
            <size>0.8 0.3 1.3</size>
          </box>
        </geometry>
      </collision>
      <collision name="Wheelchair3">
        <pose>0.1 0.01 0.45 0 0 -1.57</pose>
        <geometry>
          <box>
            <size>1.12 0.65 0.5</size>
          </box>
        </geometry>
      </collision>

      <visual name="Wheelchair">
        <geometry>
          <mesh>
            <uri>model://intellwheels_desc/meshes/chair.dae</uri>
            <scale>0.25952 0.24638 0.17893</scale>
          </mesh>
        </geometry>
        <material>
          <ambient>0.24 0.4 0.42 1</ambient>
          <diffuse>0.31 0.51 0.53 1</diffuse>
          <specular>0.2 0.2 0.2 0</specular>
          <emissive>0.1 0 0.1 1</emissive>
        </material>
      </visual>

    </link>

    <joint name="base_joint" type="fixed">
      <parent>base_footprint</parent>
      <child>base_link</child>
      <pose>0 0 0.28 0 0 0</pose>
    </joint>


    <!--    *********************************   SMALL WHEEL 1   ******************************    -->

    <link name="Link_Cylinder1">
      <pose>0.47 0.3 0.28 0 0 -3.10176</pose>
      <inertial>
        <mass>0.5</mass>
        <inertia>
          <ixx>0.001</ixx>
          <ixy>0</ixy>
          <ixz>0</ixz>
          <iyy>0.001</iyy>
          <iyz>0</iyz>
          <izz>0.001</izz>
        </inertia>
      </inertial>

      <collision name="Cylinder1">
        <pose>0.0 0 0.05 -0.4 0.0 -1.57</pose>
        <geometry>
          <cylinder>
            <radius>.015</radius>
            <length>.15</length>
          </cylinder>
        </geometry>
      </collision>

      <visual name="Cylinder1">
        <geometry>
          <mesh>
            <uri>model://intellwheels_desc/meshes/caster_arm.dae</uri>
            <scale>0.00951 0.00951 0.1731</scale>
          </mesh>
        </geometry>
      </visual>
    </link>

    <link name="Link_wheel1">
      <pose>0.50 0.3 0.12 0 0 3.14</pose>

      <inertial>
        <mass>1.0</mass>
        <inertia>
          <ixx>0.001</ixx>
          <ixy>0</ixy>
          <ixz>0</ixz>
          <iyy>0.001</iyy>
          <iyz>0</iyz>
          <izz>0.001</izz>
        </inertia>
      </inertial>

      <collision name="small_wheel_1">
        <pose>0.0 0.0 0.0 0 1.57 -1.57</pose>
          <geometry>
            <cylinder>
              <radius>0.115</radius>
              <length>0.05</length>
            </cylinder>
          </geometry>
          <surface>
          <friction>
            <ode>
              <mu>1</mu>
              <mu2>1</mu2>
            </ode>
          </friction>
        </surface>
      </collision>

      <visual name="wheel1">
      <pose>0.0 0.0 0.0 0 0.0 3.14</pose>
        <geometry>
          <mesh>
            <uri>model://intellwheels_desc/meshes/wheel.dae</uri>
            <scale>0.01306 0.01306 0.01306</scale>
          </mesh>
        </geometry>
      </visual>
    </link>


        <!--    *********************************   SMALL WHEEL 2   ******************************    -->

    <link name="Link_Cylinder2">
      <pose>0.47 -0.313 0.28 0 0 3.18</pose>
      <inertial>
        <mass>0.5</mass>
        <inertia>
          <ixx>0.001</ixx>
          <ixy>0</ixy>
          <ixz>0</ixz>
          <iyy>0.001</iyy>
          <iyz>0</iyz>
          <izz>0.001</izz>
        </inertia>
      </inertial>

      <collision name="Cylinder2">
        <pose>0.0 0 0.05 -0.4 0.0 -1.57</pose>
        <geometry>
          <cylinder>
            <radius>.015</radius>
            <length>.15</length>
          </cylinder>
        </geometry>
      </collision>

      <visual name="Cylinder2">
        <geometry>
          <mesh>
            <uri>model://intellwheels_desc/meshes/caster_arm.dae</uri>
            <scale>0.00951 0.00951 0.1731</scale>
          </mesh>
        </geometry>
      </visual>
    </link>

    <link name="Link_wheel2">
      <pose>0.50 -0.313 0.12 0 0 0.0</pose>

      <inertial>
        <mass>1.0</mass>
        <inertia>
          <ixx>0.001</ixx>
          <ixy>0</ixy>
          <ixz>0</ixz>
          <iyy>0.001</iyy>
          <iyz>0</iyz>
          <izz>0.001</izz>
        </inertia>
      </inertial>

      <collision name="small_wheel_2">
      <pose>0.0 0.0 0.0 0 1.57 -1.57</pose>
        <geometry>
          <cylinder>
            <radius>0.115</radius>
            <length>0.05</length>
          </cylinder>
        </geometry>
        <surface>
          <friction>
            <ode>
              <mu>1</mu>
              <mu2>1</mu2>
            </ode>
          </friction>
        </surface>
      </collision>

      <visual name="wheel2">
        <pose>0.0 0.0 0.0 0 0.0 3.14</pose>
        <geometry>
          <mesh>
            <uri>model://intellwheels_desc/meshes/wheel.dae</uri>
            <scale>0.01306 0.01306 0.01306</scale>
          </mesh>
        </geometry>
      </visual>
    </link>

    <!--    *********************************   SMALL WHEEL 3   ******************************    -->

    <link name="Link_Cylinder3">
      <pose>-0.52 0.3 0.28 0 0 -0.04</pose>
      <inertial>
        <mass>0.5</mass>
        <inertia>
          <ixx>0.001</ixx>
          <ixy>0</ixy>
          <ixz>0</ixz>
          <iyy>0.001</iyy>
          <iyz>0</iyz>
          <izz>0.001</izz>
        </inertia>
      </inertial>

      <collision name="Cylinder3">
        <pose>0.0 0 0.05 -0.4 0.0 -1.57</pose>
        <geometry>
          <cylinder>
            <radius>.015</radius>
            <length>.15</length>
          </cylinder>
        </geometry>
      </collision>

      <visual name="Cylinder3">
        <geometry>
          <mesh>
            <uri>model://intellwheels_desc/meshes/caster_arm.dae</uri>
            <scale>0.00951 0.00951 0.1731</scale>
          </mesh>
        </geometry>
      </visual>
    </link>

    <link name="Link_wheel3">
      <pose>-0.545 0.3 0.12 0 0 3.14</pose>

      <inertial>
        <mass>1.0</mass>
        <inertia>
          <ixx>0.001</ixx>
          <ixy>0</ixy>
          <ixz>0</ixz>
          <iyy>0.001</iyy>
          <iyz>0</iyz>
          <izz>0.001</izz>
        </inertia>
      </inertial>

      <collision name="small_wheel_3">
      <pose>0.0 0.0 0.0 0 1.57 -1.57</pose>
        <geometry>
          <cylinder>
            <radius>0.115</radius>
            <length>0.05</length>
          </cylinder>
        </geometry>
        <surface>
          <friction>
            <ode>
              <mu>1</mu>
              <mu2>1</mu2>
            </ode>
          </friction>
        </surface>
      </collision>

      <visual name="wheel3">
        <pose>0.0 0.0 0.0 0 0.0 3.14</pose>
        <geometry>
          <mesh>
            <uri>model://intellwheels_desc/meshes/wheel.dae</uri>
            <scale>0.01306 0.01306 0.01306</scale>
          </mesh>
        </geometry>
      </visual>
    </link>

<!--    *********************************   SMALL WHEEL 4   ******************************    -->

    <link name="Link_Cylinder4">
      <pose>-0.52 -0.315 0.28 0 0 -1.53</pose>
      <inertial>
        <mass>0.5</mass>
        <inertia>
          <ixx>0.001</ixx>
          <ixy>0</ixy>
          <ixz>0</ixz>
          <iyy>0.001</iyy>
          <iyz>0</iyz>
          <izz>0.001</izz>
        </inertia>
      </inertial>

      <collision name="Cylinder4">
        <pose>0.0 0 0.05 -0.4 0.0 -1.57</pose>
        <geometry>
          <cylinder>
            <radius>.015</radius>
            <length>.15</length>
          </cylinder>
        </geometry>
      </collision>

      <visual name="Cylinder4">
        <geometry>
          <mesh>
            <uri>model://intellwheels_desc/meshes/caster_arm_old.dae</uri>
            <scale>0.00951 0.00951 0.1731</scale>
          </mesh>
        </geometry>
      </visual>
    </link>

    <link name="Link_wheel4">
      <pose>-0.545 -0.315 0.12 0 0 0.0</pose>

      <inertial>
        <mass>1.0</mass>
        <inertia>
          <ixx>0.001</ixx>
          <ixy>0</ixy>
          <ixz>0</ixz>
          <iyy>0.001</iyy>
          <iyz>0</iyz>
          <izz>0.001</izz>
        </inertia>
      </inertial>

      <collision name="small_wheel_4">
      <pose>0.0 0.0 0.0 0 1.57 -1.57</pose>
        <geometry>
          <cylinder>
            <radius>0.115</radius>
            <length>0.05</length>
          </cylinder>
        </geometry>
        <surface>
          <friction>
            <ode>
              <mu>1</mu>
              <mu2>1</mu2>
            </ode>
          </friction>
        </surface>
      </collision>

      <visual name="wheel4">
        <pose>0.0 0.0 0.0 0 0.0 3.14</pose>
        <geometry>
          <mesh>
            <uri>model://intellwheels_desc/meshes/wheel.dae</uri>
            <scale>0.01306 0.01306 0.01306</scale>
          </mesh>
        </geometry>
      </visual>
    </link>

<!--    *********************************   BIG WHEEL 1   ******************************    -->
    <link name="Link_GWheel1">
      <pose>0.0 0.378 0.2166 0 0 0.0</pose>

      <inertial>
        <mass>3.0</mass>
        <inertia>
          <ixx>0.001</ixx>
          <ixy>0</ixy>
          <ixz>0</ixz>
          <iyy>0.001</iyy>
          <iyz>0</iyz>
          <izz>0.001</izz>
        </inertia>
      </inertial>

      <collision name="Cylinder">
        <pose>0.0 0.0 0.0 0.0 1.57 -1.57</pose>
        <geometry>
          <cylinder>
            <radius>0.2116</radius>
            <length>0.092</length>
          </cylinder>
        </geometry>
        <surface>
          <friction>
            <ode>
              <mu>1</mu>
              <mu2>1</mu2>
            </ode>
          </friction>
        </surface>
      </collision>

      <visual name="Gwheel1_wheel">
        <material>
          <ambient>0.64 0.64 0.64 1.0</ambient>
          <diffuse>0.64 0.64 0.64 1.0</diffuse>
          <specular>0.5 0.5 0.5 1.0</specular>
        </material>
        <geometry>
          <mesh>
            <uri>model://intellwheels_desc/meshes/wheel.dae</uri>
            <scale>0.024 0.024 0.024</scale>
          </mesh>
        </geometry>
      </visual>

    </link>


    <!--    *********************************   BIG WHEEL 2   ******************************    -->
    <link name="Link_GWheel2">
      <pose>0 -0.4 0.2166 0 0 3.14</pose>

      <inertial>
        <mass>3.0</mass>
        <inertia>
          <ixx>0.001</ixx>
          <ixy>0</ixy>
          <ixz>0</ixz>
          <iyy>0.001</iyy>
          <iyz>0</iyz>
          <izz>0.001</izz>
        </inertia>
      </inertial>

      <collision name="Cylinder">
        <pose>0.0 0.0 0.0 0.0 1.57 -1.57</pose>
        <geometry>
          <cylinder>
            <radius>0.2116</radius>
            <length>0.092</length>
          </cylinder>
        </geometry>
        <surface>
          <friction>
            <ode>
              <mu>1</mu>
              <mu2>1</mu2>
            </ode>
          </friction>
        </surface>
      </collision>

      <visual name="Gwheel2_wheel">
        <material>
          <ambient>0.64 0.64 0.64 1.0</ambient>
          <diffuse>0.64 0.64 0.64 1.0</diffuse>
          <specular>0.5 0.5 0.5 1.0</specular>
        </material>
        <geometry>
          <mesh>
            <uri>model://intellwheels_desc/meshes/wheel.dae</uri>
            <scale>0.024 0.024 0.024</scale>
          </mesh>
        </geometry>
      </visual>

    </link>


    <!--    *********************************  JOINS SMALL WHEEL 1   ******************************    -->

    <joint name="Link_Cylinder1" type="revolute">
      <parent>base_link</parent>
      <child>Link_Cylinder1</child>
      <pose>0.035 0.0  0.04 0.0 0.0 0.0</pose>
      <axis>
        <xyz>0 0 1.0</xyz>
        <dynamics>
          <damping>0.0</damping>
          <friction>1.0</friction>
        </dynamics>
        <limit>
          <lower></lower>
          <upper></upper>
          <effort>5</effort>
          <velocity>5</velocity>
        </limit>
      </axis>
    </joint>

    <joint name="Link_wheel1" type="revolute">
      <parent>Link_Cylinder1</parent>
      <child>Link_wheel1</child>
      <pose>0.0 0.0 0.0 0.0 0.0 0.0</pose>
      <axis>
        <xyz>0 1 0</xyz>
        <limit>
          <lower></lower>
          <upper></upper>
          <effort>10</effort>
          <velocity>0</velocity>
        </limit>
      </axis>
    </joint>

<!--    *********************************  JOINS SMALL WHEEL 2   ******************************    -->

    <joint name="Link_Cylinder2" type="revolute">
      <parent>base_link</parent>
      <child>Link_Cylinder2</child>
      <pose>0.035 0.0  0.04 0.0 0.0 0.0</pose>
      <axis>
        <xyz>0 0 1.0</xyz>
        <dynamics>
          <damping>0.0</damping>
          <friction>1.0</friction>
        </dynamics>
        <limit>
          <lower></lower>
          <upper></upper>
          <effort>5</effort>
          <velocity>2</velocity>
        </limit>
      </axis>
    </joint>

    <joint name="Link_wheel2" type="revolute">
      <parent>Link_Cylinder2</parent>
      <child>Link_wheel2</child>
      <pose>0.0 0.0 0.0 0.0 0.0 0.0</pose>
      <axis>
        <xyz>0 1 0</xyz>
        <limit>
          <lower></lower>
          <upper></upper>
          <effort>10</effort>
          <velocity>0</velocity>
        </limit>
      </axis>
    </joint>


<!--    *********************************  JOINS SMALL WHEEL 3   ******************************    -->

    <joint name="Link_Cylinder3" type="revolute">
      <parent>base_link</parent>
      <child>Link_Cylinder3</child>
      <pose>0.035 0.0  0.04 0.0 0.0 0.0</pose>
      <axis>
        <xyz>0 0 1.0</xyz>
        <dynamics>
          <damping>0.0</damping>
          <friction>1.0</friction>
        </dynamics>
        <limit>
          <lower></lower>
          <upper></upper>
          <effort>5</effort>
          <velocity>5</velocity>
        </limit>
      </axis>
    </joint>

    <joint name="Link_wheel3" type="revolute">
      <parent>Link_Cylinder3</parent>
      <child>Link_wheel3</child>
      <pose>0.0 0.0 0.0 0.0 0.0 0.0</pose>
      <axis>
        <xyz>0 1 0</xyz>
        <limit>
          <lower></lower>
          <upper></upper>
          <effort>10</effort>
          <velocity>0</velocity>
        </limit>
      </axis>
    </joint>

<!--    *********************************  JOINS SMALL WHEEL 4   ******************************    -->


    <joint name="Link_Cylinder4" type="revolute">
      <parent>base_link</parent>
      <child>Link_Cylinder4</child>
      <pose>0.0 0.035 0.04 0.0 0.0 1.57</pose>
      <axis>
        <xyz>0 0 1.0</xyz>
        <dynamics>
          <damping>0.0</damping>
          <friction>1.0</friction>
        </dynamics>
        <limit>
          <lower></lower>
          <upper></upper>
          <effort>5</effort>
          <velocity>5</velocity>
        </limit>
      </axis>
    </joint>

    <joint name="Link_wheel4" type="revolute">
      <parent>Link_Cylinder4</parent>
      <child>Link_wheel4</child>
      <pose>0.0 0.0 0.0 0.0 0.0 0.0</pose>
      <axis>
        <xyz>0 1 0</xyz>
        <limit>
          <lower></lower>
          <upper></upper>
          <effort>10</effort>
          <velocity>0</velocity>
        </limit>
      </axis>
    </joint>


<!--    *********************************  JOINS BIG WHEEL 1   ******************************    -->

    <joint name="Link_GWheel1" type="revolute">
      <parent>base_link</parent>
      <child>Link_GWheel1</child>
      <pose>0.0 0.0 0.0 0.0 0.0 0.0</pose>
      <axis>
        <xyz>0 1 0</xyz>
        <limit>
          <lower></lower>
          <upper></upper>
          <effort>0</effort>
          <velocity>0</velocity>
        </limit>
      </axis>
    </joint>


<!--    *********************************  JOINS BIG WHEEL 2   ******************************    -->

    <joint name="Link_GWheel2" type="revolute">
      <parent>base_link</parent>
      <child>Link_GWheel2</child>
      <pose>0.0 0.0 0.0 0.0 0.0 3.14</pose>
      <axis>
        <xyz>0 1 0</xyz>
        <limit>
          <lower></lower>
          <upper></upper>
          <effort>0</effort>
          <velocity>0</velocity>
        </limit>
      </axis>
    </joint>

<!--    *********************************  JOINS BIG WHEEL 2   ******************************    -->

 <plugin name='differential_drive_controller' filename='libgazebo_ros_diff_drive.so'>
		<publishWheelTF>false</publishWheelTF>
		<publishWheelJointState>false</publishWheelJointState>
		<alwaysOn>true</alwaysOn>
		<updateRate>30</updateRate>
		<rightJoint>Link_GWheel2</rightJoint>
		<leftJoint>Link_GWheel1</leftJoint>
		<wheelSeparation>0.55</wheelSeparation>
		<wheelDiameter>0.35</wheelDiameter>
		<wheelTorque>200</wheelTorque>
		<commandTopic>cmd_vel</commandTopic>
		<odometryTopic>odom</odometryTopic>
		<odometryFrame>odom</odometryFrame>
		<robotBaseFrame>base_footprint</robotBaseFrame>
		<robotNamespace>/</robotNamespace>
		<legacyMode>false</legacyMode>
  	<rosDebugLevel>na</rosDebugLevel>
		<wheelAcceleration>0</wheelAcceleration>
    <publishTf>true</publishTf>
    <publishOdomTF>true</publishOdomTF>
    <odometrySource>world</odometrySource>
  </plugin>

  </model>



</sdf>


